

--Lilly Pilly 03 Tree
	local N = gal_ecology_trees.N

	
	return {
	yslice_prob = {
		
	},
	size = {
		y = 19,
		x = 11,
		z = 11
	},
	data = {
		N["_____"],N["_____"],N["_____"],N["_____"],N["_____"],N["_____"],N["_____"],N["_____"],N["_____"],N["_____"],N["_____"],N["_____"],N["_____"],N["_____"],N["_____"],N["_____"],N["_____"],N["_____"],N["_____"],N["_____"],N["_____"],N["_____"],N["_____"],N["_____"],N["_____"],N["_____"],N["_____"],N["_____"],N["_____"],N["_____"],N["_____"],N["_____"],N["_____"],N["_____"],N["_____"],N["_____"],N["_____"],N["_____"],N["_____"],N["_____"],N["_____"],N["_____"],N["_____"],N["_____"],N["_____"],N["_____"],N["_____"],N["_____"],N["_____"],N["_____"],N["_____"],N["_____"],N["_____"],N["_____"],N["_____"],N["_____"],N["_____"],N["_____"],N["_____"],N["_____"],N["_____"],N["_____"],N["_____"],N["_____"],N["_____"],N["_____"],N["_____"],N["_____"],N["_____"],N["_____"],N["_____"],N["_____"],N["_____"],N["_____"],N["_____"],N["_____"],N["_____"],N["_____"],N["_____"],N["_____"],N["_____"],N["_____"],N["_____"],N["_____"],N["_____"],N["_____"],N["_____"],N["_____"],N["_____"],N["_____"],N["_____"],N["_____"],N["_____"],N["_____"],N["_____"],N["_____"],N["_____"],N["_____"],N["_____"],N["_____"],N["_____"],N["_____"],N["_____"],N["_____"],N["_____"],N["_____"],N["_____"],N["_____"],N["_____"],N["_____"],N["_____"],N["_____"],N["_____"],N["_____"],N["_____"],N["_____"],N["_____"],N["_____"],N["_____"],N["_____"],N["_____"],N["_____"],N["_____"],N["_____"],N["_____"],N["_____"],N["_____"],N["_____"],N["_____"],N["_____"],N["_____"],N["_____"],N["_____"],N["_____"],N["_____"],N["_____"],N["_____"],N["_____"],N["_____"],N["_____"],N["_____"],N["_____"],N["_____"],N["_____"],N["_____"],N["_____"],N["_____"],N["_____"],N["_____"],N["_____"],N["_____"],N["_____"],N["_____"],N["_____"],N["_____"],N["_____"],N["_____"],N["_____"],N["_____"],N["_____"],N["_____"],N["_____"],N["_____"],N["_____"],N["_____"],N["_____"],N["_____"],N["_____"],N["_____"],N["_____"],N["_____"],N["_____"],N["_____"],N["_____"],N["_____"],N["_____"],N["_____"],N["_____"],N["_____"],N["_____"],N["_____"],N["_____"],N["_____"],N["_____"],N["_____"],N["_____"],N["_____"],N["_____"],N["_____"],N["_____"],N["_____"],N["_____"],N["_____"],N["_____"],N["_____"],N["_____"],N["_____"],N["_____"],N["_____"],N["_____"],N["_____"],N["_____"],N["_____"],N["_____"],N["_____"],N["_____"],N["_____"],N["_____"],N["_____"],N["_____"],N["_____"],N["_____"],N["_____"],N["_____"],N["_____"],N["_____"],N["_____"],N["_____"],N["_____"],N["_____"],N["_____"],N["_____"],N["_____"],N["_____"],N["_____"],N["_____"],N["_____"],N["_____"],N["_____"],N["_____"],N["_____"],N["_____"],N["_____"],N["_____"],N["_____"],N["_____"],N["_____"],N["_____"],N["_____"],N["_____"],N["_____"],N["_____"],N["_____"],N["_____"],N["_____"],N["_____"],N["_____"],N["_____"],N["_____"],N["_____"],N["_____"],N["_____"],N["_____"],N["_____"],N["_____"],N["_____"],N["_____"],N["_____"],N["_____"],N["_____"],N["_____"],N["_____"],N["_____"],N["_____"],N["_____"],N["_____"],N["_____"],N["_____"],N["_____"],N["_____"],N["_____"],N["_____"],N["_____"],N["_____"],N["_____"],N["_____"],N["_____"],N["_____"],N["_____"],N["_____"],N["_____"],N["_____"],N["_____"],N["_____"],N["_____"],N["_____"],N["_____"],N["_____"],N["_____"],N["_____"],N["_____"],N["_____"],N["_____"],N["_____"],N["_____"],N["_____"],N["_____"],N["_____"],N["_____"],N["_____"],N["_____"],N["_____"],N["_____"],N["_____"],N["_____"],N["_____"],N["_____"],N["_____"],N["_____"],N["_____"],N["_____"],N["_____"],N["_____"],N["_____"],N["_____"],N["_____"],N["_____"],N["_____"],N["_____"],N["_____"],N["_____"],N["_____"],N["_____"],
		N["L0m02"],
		N["_____"],
		N["L0m02"],
		N["_____"],N["_____"],N["_____"],N["_____"],N["_____"],N["_____"],N["_____"],N["_____"],N["_____"],N["_____"],N["_____"],N["_____"],N["_____"],N["_____"],N["_____"],N["_____"],N["_____"],N["_____"],N["_____"],N["_____"],N["_____"],N["_____"],N["_____"],N["_____"],N["_____"],N["_____"],N["_____"],N["_____"],N["_____"],N["_____"],N["_____"],N["_____"],N["_____"],N["_____"],N["_____"],N["_____"],N["_____"],N["_____"],N["_____"],N["_____"],N["_____"],N["_____"],N["_____"],N["_____"],N["_____"],N["_____"],N["_____"],N["_____"],N["_____"],N["_____"],N["_____"],N["_____"],N["_____"],N["_____"],N["_____"],N["_____"],N["_____"],N["_____"],N["_____"],N["_____"],N["_____"],N["_____"],N["_____"],N["_____"],N["_____"],N["_____"],N["_____"],N["_____"],N["_____"],N["_____"],N["_____"],N["_____"],N["_____"],N["_____"],N["_____"],N["_____"],N["_____"],N["_____"],N["_____"],N["_____"],N["_____"],N["_____"],N["_____"],N["_____"],N["_____"],N["_____"],N["_____"],N["_____"],N["_____"],N["_____"],N["_____"],N["_____"],N["_____"],N["_____"],N["_____"],N["_____"],N["_____"],N["_____"],N["_____"],N["_____"],N["_____"],N["_____"],N["_____"],N["_____"],N["_____"],N["_____"],N["_____"],N["_____"],N["_____"],N["_____"],N["_____"],N["_____"],N["_____"],N["_____"],N["_____"],N["_____"],N["_____"],N["_____"],N["_____"],N["_____"],N["_____"],N["_____"],N["_____"],N["_____"],N["_____"],N["_____"],N["_____"],N["_____"],N["_____"],N["_____"],N["_____"],N["_____"],N["_____"],N["_____"],N["_____"],N["_____"],N["_____"],N["_____"],N["_____"],N["_____"],N["_____"],N["_____"],N["_____"],N["_____"],N["_____"],N["_____"],N["_____"],N["_____"],N["_____"],N["_____"],N["_____"],N["_____"],N["_____"],N["_____"],N["_____"],N["_____"],N["_____"],N["_____"],N["_____"],N["_____"],N["_____"],N["_____"],N["_____"],N["_____"],N["_____"],N["_____"],N["_____"],N["_____"],N["_____"],N["_____"],N["_____"],N["_____"],N["_____"],N["_____"],
		N["L0m02"],
		N["_____"],N["_____"],N["_____"],N["_____"],N["_____"],N["_____"],N["_____"],N["_____"],
		N["L0m02"],
		N["L0m02"],
		N["L0m02"],
		N["L0m02"],
		N["L0m02"],
		N["_____"],N["_____"],N["_____"],N["_____"],N["_____"],
		N["L0m02"],
		N["L0m02"],
		N["L0m02"],
		N["L0m02"],
		N["L0m02"],
		N["L0m02"],
		N["L0m02"],
		N["_____"],N["_____"],N["_____"],N["_____"],
		N["L0m02"],
		N["L0m02"],
		N["L0m01"],
		N["L0m02"],
		N["L0m01"],
		N["L0m02"],
		N["L0m02"],
		N["_____"],N["_____"],N["_____"],N["_____"],
		N["L0m02"],
		N["L0m02"],
		{name = "australia:lilly_pilly_berries",param1 = 127},
		N["L0m02"],
		N["L0m02"],
		N["L0m02"],
		N["L0m02"],
		N["_____"],N["_____"],N["_____"],N["_____"],N["_____"],
		N["L0m02"],
		N["L0m02"],
		N["L0m02"],
		{name = "australia:lilly_pilly_berries",param1 = 127},
		N["L0m02"],
		N["_____"],N["_____"],N["_____"],N["_____"],N["_____"],N["_____"],N["_____"],N["_____"],N["_____"],
		N["L0m02"],
		N["_____"],N["_____"],N["_____"],N["_____"],N["_____"],N["_____"],N["_____"],N["_____"],N["_____"],N["_____"],N["_____"],N["_____"],N["_____"],N["_____"],N["_____"],N["_____"],N["_____"],N["_____"],N["_____"],N["_____"],
		N["L0m02"],
		N["_____"],N["_____"],N["_____"],N["_____"],N["_____"],N["_____"],N["_____"],N["_____"],N["_____"],N["_____"],N["_____"],N["_____"],N["_____"],N["_____"],N["_____"],N["_____"],N["_____"],N["_____"],N["_____"],N["_____"],N["_____"],N["_____"],N["_____"],N["_____"],N["_____"],N["_____"],N["_____"],N["_____"],N["_____"],N["_____"],N["_____"],N["_____"],N["_____"],N["_____"],N["_____"],N["_____"],N["_____"],N["_____"],N["_____"],N["_____"],N["_____"],N["_____"],N["_____"],N["_____"],N["_____"],N["_____"],N["_____"],N["_____"],N["_____"],N["_____"],N["_____"],N["_____"],N["_____"],N["_____"],N["_____"],N["_____"],N["_____"],N["_____"],N["_____"],N["_____"],N["_____"],N["_____"],N["_____"],N["_____"],N["_____"],N["_____"],N["_____"],N["_____"],N["_____"],N["_____"],N["_____"],N["_____"],N["_____"],N["_____"],N["_____"],N["_____"],N["_____"],N["_____"],N["_____"],N["_____"],N["_____"],N["_____"],N["_____"],N["_____"],N["_____"],N["_____"],N["_____"],N["_____"],N["_____"],N["_____"],N["_____"],N["_____"],N["_____"],N["_____"],N["_____"],N["_____"],N["_____"],
		N["L0m02"],
		N["L0m02"],
		N["L0m02"],
		N["_____"],N["_____"],N["_____"],N["_____"],N["_____"],N["_____"],N["_____"],
		N["L0m02"],
		N["L0m02"],
		N["L0m02"],
		N["L0m02"],
		N["L0m02"],
		N["_____"],N["_____"],N["_____"],N["_____"],N["_____"],N["_____"],
		N["L0m02"],
		N["L0m02"],
		N["L0m01"],
		N["L0m02"],
		N["L0m02"],
		N["_____"],N["_____"],N["_____"],N["_____"],N["_____"],
		N["L0m02"],
		N["L0m02"],
		N["L0m02"],
		N["L0m02"],
		N["L0m02"],
		N["L0m02"],
		N["L0m02"],
		N["_____"],N["_____"],N["_____"],N["_____"],
		N["L0m02"],
		N["L0m01"],
		N["L0m01"],
		N["L0m01"],
		N["L0m01"],
		N["L0m01"],
		{name = "australia:lilly_pilly_berries",param1 = 127},
		N["_____"],N["_____"],N["_____"],N["_____"],
		N["L0m02"],
		N["L0m01"],
		N["L0m00"],
		N["L0m01"],
		N["L0m00"],
		N["L0m01"],
		N["L0m02"],
		N["_____"],N["_____"],N["_____"],N["_____"],
		N["L0m02"],
		N["L0m01"],
		N["L0m01"],
		N["L0m01"],
		N["L0m01"],
		N["L0m01"],
		N["L0m02"],
		N["_____"],N["_____"],N["_____"],N["_____"],
		N["L0m02"],
		N["L0m02"],
		N["L0m01"],
		N["L0m02"],
		N["L0m02"],
		{name = "australia:lilly_pilly_berries",param1 = 127},
		N["L0m02"],
		N["_____"],N["_____"],N["_____"],N["_____"],
		N["L0m02"],
		N["L0m02"],
		N["L0m02"],
		N["L0m02"],
		N["L0m01"],
		N["L0m02"],
		N["L0m02"],
		N["_____"],N["_____"],N["_____"],N["_____"],N["_____"],
		N["L0m02"],
		N["L0m02"],
		N["L0m02"],
		N["L0m02"],
		N["L0m02"],
		N["L0m02"],
		N["_____"],N["_____"],N["_____"],N["_____"],N["_____"],
		N["L0m02"],
		N["L0m02"],
		N["L0m01"],
		N["L0m02"],
		N["L0m02"],
		N["_____"],N["_____"],N["_____"],N["_____"],N["_____"],N["_____"],
		N["L0m02"],
		N["L0m02"],
		N["L0m02"],
		N["L0m02"],
		N["L0m02"],
		N["_____"],N["_____"],N["_____"],N["_____"],N["_____"],N["_____"],N["_____"],
		N["L0m02"],
		N["L0m02"],
		N["L0m02"],
		N["_____"],N["_____"],N["_____"],N["_____"],N["_____"],N["_____"],N["_____"],N["_____"],N["_____"],N["_____"],N["_____"],N["_____"],N["_____"],N["_____"],N["_____"],N["_____"],N["_____"],N["_____"],N["_____"],N["_____"],N["_____"],N["_____"],N["_____"],N["_____"],N["_____"],N["_____"],N["_____"],N["_____"],N["_____"],N["_____"],N["_____"],N["_____"],N["_____"],N["_____"],N["_____"],N["_____"],N["_____"],N["_____"],N["_____"],N["_____"],N["_____"],N["_____"],N["_____"],N["_____"],N["_____"],N["_____"],N["_____"],N["_____"],N["_____"],N["_____"],N["_____"],N["_____"],N["_____"],N["_____"],N["_____"],N["_____"],N["_____"],N["_____"],N["_____"],N["_____"],N["_____"],N["_____"],N["_____"],N["_____"],N["_____"],N["_____"],N["_____"],N["_____"],N["_____"],N["_____"],N["_____"],N["_____"],N["_____"],
		N["L0m02"],
		N["L0m02"],
		N["L0m02"],
		N["L0m02"],
		N["L0m02"],
		N["_____"],N["_____"],N["_____"],N["_____"],N["_____"],N["_____"],
		N["L0m02"],
		N["L0m01"],
		N["L0m01"],
		N["L0m01"],
		N["L0m02"],
		N["_____"],N["_____"],N["_____"],N["_____"],N["_____"],N["_____"],
		N["L0m02"],
		N["L0m01"],
		N["L0m00"],
		N["L0m01"],
		N["L0m02"],
		N["L0m02"],
		N["_____"],N["_____"],N["_____"],N["_____"],
		N["L0m02"],
		N["L0m02"],
		N["L0m01"],
		N["L0m01"],
		N["L0m01"],
		N["L0m01"],
		{name = "australia:lilly_pilly_berries",param1 = 127},
		N["_____"],N["_____"],N["_____"],N["_____"],
		N["L0m02"],
		N["L0m01"],
		N["L0m00"],
		N["L0m01"],
		N["L0m00"],
		N["L0m01"],
		N["L0m02"],
		N["_____"],N["_____"],N["_____"],
		N["L0m02"],
		N["L0m01"],
		N["L0m00"],
		N["T0m00"],
		N["L0m00"],
		N["T0m00"],
		N["L0m00"],
		N["L0m01"],
		N["L0m02"],
		N["_____"],N["_____"],N["_____"],
		N["L0m02"],
		N["L0m01"],
		N["L0m00"],
		N["L0m01"],
		N["L0m00"],
		N["L0m01"],
		N["L0m02"],
		N["_____"],N["_____"],N["_____"],N["_____"],
		N["L0m02"],
		N["L0m01"],
		N["L0m00"],
		N["L0m01"],
		N["L0m01"],
		N["L0m01"],
		N["L0m02"],
		N["_____"],N["_____"],N["_____"],N["_____"],
		N["L0m02"],
		N["L0m01"],
		N["L0m01"],
		N["L0m01"],
		N["L0m00"],
		N["L0m01"],
		N["L0m02"],
		N["_____"],N["_____"],N["_____"],N["_____"],
		N["L0m02"],
		N["L0m02"],
		N["L0m01"],
		N["L0m01"],
		N["L0m01"],
		N["L0m01"],
		N["L0m02"],
		N["_____"],N["_____"],N["_____"],N["_____"],N["_____"],
		N["L0m02"],
		N["L0m01"],
		N["L0m00"],
		N["L0m01"],
		N["L0m02"],
		N["L0m02"],
		N["_____"],N["_____"],N["_____"],N["_____"],N["_____"],
		N["L0m02"],
		N["L0m01"],
		N["L0m01"],
		N["L0m01"],
		N["L0m02"],
		N["_____"],N["_____"],N["_____"],N["_____"],N["_____"],N["_____"],
		N["L0m02"],
		N["L0m02"],
		N["L0m02"],
		N["L0m02"],
		N["L0m02"],
		N["_____"],N["_____"],N["_____"],N["_____"],N["_____"],N["_____"],N["_____"],N["_____"],N["_____"],N["_____"],N["_____"],N["_____"],N["_____"],N["_____"],N["_____"],N["_____"],N["_____"],N["_____"],N["_____"],N["_____"],N["_____"],N["_____"],N["_____"],N["_____"],N["_____"],N["_____"],N["_____"],N["_____"],N["_____"],N["_____"],
		N["T0m00"],
		N["_____"],N["_____"],N["_____"],N["_____"],N["_____"],N["_____"],N["_____"],N["_____"],N["_____"],N["_____"],
		N["T0m00"],
		N["_____"],N["_____"],N["_____"],N["_____"],N["_____"],N["_____"],N["_____"],N["_____"],N["_____"],N["_____"],
		N["T0m00"],
		N["_____"],N["_____"],N["_____"],N["_____"],N["_____"],N["_____"],N["_____"],N["_____"],N["_____"],N["_____"],
		N["T0m00"],
		N["_____"],N["_____"],N["_____"],N["_____"],N["_____"],N["_____"],N["_____"],N["_____"],
		N["L0m02"],
		N["L0m02"],
		N["T0m00"],
		N["L0m02"],
		N["L0m02"],
		N["_____"],N["_____"],N["_____"],N["_____"],N["_____"],N["_____"],
		N["L0m02"],
		N["L0m01"],
		N["T0m00"],
		N["L0m01"],
		N["L0m02"],
		N["_____"],N["_____"],N["_____"],N["_____"],N["_____"],
		{name = "australia:lilly_pilly_berries",param1 = 127},
		N["L0m01"],
		N["L0m00"],
		N["T0m00"],
		N["L0m00"],
		N["L0m01"],
		N["L0m02"],
		N["_____"],N["_____"],N["_____"],N["_____"],
		N["L0m02"],
		N["L0m02"],
		N["L0m01"],
		N["T0m00"],
		N["L0m00"],
		N["L0m01"],
		N["L0m02"],
		N["_____"],N["_____"],N["_____"],N["_____"],
		{name = "australia:lilly_pilly_berries",param1 = 127},
		N["L0m01"],
		N["L0m01"],
		N["T0m00"],
		N["T0m00"],
		N["L0m00"],
		N["L0m01"],
		N["L0m02"],
		N["_____"],N["_____"],N["_____"],
		N["L0m02"],
		N["L0m01"],
		N["L0m00"],
		N["T0m00"],
		N["L0m00"],
		N["L0m01"],
		N["L0m02"],
		N["_____"],N["_____"],N["_____"],N["_____"],
		N["L0m02"],
		N["L0m01"],
		N["L0m00"],
		N["L0m00"],
		N["L0m01"],
		N["L0m01"],
		{name = "australia:lilly_pilly_berries",param1 = 127},
		N["_____"],N["_____"],N["_____"],
		N["L0m02"],
		N["L0m01"],
		N["L0m00"],
		N["T0m00"],
		N["L0m00"],
		N["L0m00"],
		N["L0m01"],
		{name = "australia:lilly_pilly_berries",param1 = 127},
		N["_____"],N["_____"],N["_____"],N["_____"],
		N["L0m02"],
		N["L0m01"],
		N["L0m00"],
		N["L0m00"],
		N["T0m00"],
		N["L0m00"],
		N["L0m01"],
		N["L0m02"],
		N["_____"],N["_____"],N["_____"],
		N["L0m02"],
		N["L0m02"],
		N["L0m01"],
		N["L0m00"],
		N["L0m00"],
		N["L0m01"],
		N["L0m02"],
		N["_____"],N["_____"],N["_____"],N["_____"],
		N["L0m02"],
		N["L0m01"],
		N["L0m00"],
		N["T0m00"],
		N["L0m00"],
		N["L0m01"],
		N["L0m02"],
		N["_____"],N["_____"],N["_____"],N["_____"],N["_____"],
		N["L0m02"],
		N["L0m01"],
		N["L0m00"],
		N["L0m01"],
		N["L0m02"],
		N["_____"],N["_____"],N["_____"],N["_____"],N["_____"],N["_____"],
		N["L0m02"],
		N["L0m02"],
		N["L0m01"],
		N["L0m02"],
		N["L0m02"],
		N["_____"],N["_____"],N["_____"],N["_____"],N["_____"],N["_____"],N["_____"],N["_____"],
		N["L0m02"],
		N["_____"],N["_____"],N["_____"],N["_____"],N["_____"],N["_____"],N["_____"],N["_____"],N["_____"],N["_____"],N["_____"],N["_____"],N["_____"],N["_____"],N["_____"],N["_____"],N["_____"],N["_____"],N["_____"],N["_____"],N["_____"],N["_____"],N["_____"],N["_____"],N["_____"],N["_____"],N["_____"],N["_____"],N["_____"],N["_____"],N["_____"],N["_____"],N["_____"],N["_____"],N["_____"],N["_____"],N["_____"],N["_____"],N["_____"],N["_____"],N["_____"],N["_____"],N["_____"],N["_____"],N["_____"],N["_____"],N["_____"],N["_____"],N["_____"],N["_____"],N["_____"],N["_____"],N["_____"],N["_____"],N["_____"],N["_____"],N["_____"],N["_____"],N["_____"],N["_____"],N["_____"],N["_____"],N["_____"],
		N["L0m02"],
		N["L0m02"],
		N["L0m02"],
		N["L0m02"],
		N["L0m02"],
		N["_____"],N["_____"],N["_____"],N["_____"],N["_____"],N["_____"],
		N["L0m02"],
		N["L0m01"],
		N["L0m01"],
		N["L0m01"],
		N["L0m02"],
		N["_____"],N["_____"],N["_____"],N["_____"],N["_____"],N["_____"],
		N["L0m02"],
		N["L0m01"],
		N["L0m00"],
		N["L0m01"],
		N["L0m02"],
		N["L0m02"],
		N["_____"],N["_____"],N["_____"],N["_____"],
		N["L0m02"],
		N["L0m02"],
		N["L0m01"],
		N["L0m01"],
		N["L0m01"],
		N["L0m01"],
		N["L0m02"],
		N["_____"],N["_____"],N["_____"],N["_____"],
		N["L0m02"],
		N["L0m01"],
		N["L0m00"],
		N["L0m01"],
		N["L0m00"],
		N["L0m01"],
		N["L0m02"],
		N["_____"],N["_____"],N["_____"],
		N["L0m02"],
		N["L0m01"],
		N["L0m00"],
		N["T0m00"],
		N["L0m00"],
		N["L0m01"],
		N["L0m01"],
		N["L0m02"],
		N["_____"],N["_____"],N["_____"],N["_____"],
		N["L0m02"],
		N["L0m01"],
		N["L0m00"],
		N["L0m00"],
		N["L0m01"],
		N["L0m02"],
		N["L0m02"],
		N["_____"],N["_____"],N["_____"],N["_____"],
		{name = "australia:lilly_pilly_berries",param1 = 127},
		N["L0m01"],
		N["L0m00"],
		N["T0m00"],
		N["L0m00"],
		N["L0m01"],
		N["L0m02"],
		N["_____"],N["_____"],N["_____"],N["_____"],
		N["L0m02"],
		N["L0m01"],
		N["L0m01"],
		N["L0m00"],
		N["T0m00"],
		N["L0m00"],
		N["L0m01"],
		N["L0m02"],
		N["_____"],N["_____"],N["_____"],
		N["L0m02"],
		N["L0m02"],
		N["L0m01"],
		N["L0m01"],
		N["L0m00"],
		N["L0m01"],
		N["L0m02"],
		N["_____"],N["_____"],N["_____"],N["_____"],N["_____"],
		N["L0m02"],
		N["L0m01"],
		N["L0m00"],
		N["L0m01"],
		N["L0m02"],
		{name = "australia:lilly_pilly_berries",param1 = 127},
		N["_____"],N["_____"],N["_____"],N["_____"],N["_____"],
		N["L0m02"],
		N["L0m01"],
		N["L0m01"],
		N["L0m01"],
		N["L0m02"],
		N["_____"],N["_____"],N["_____"],N["_____"],N["_____"],N["_____"],
		N["L0m02"],
		N["L0m02"],
		N["L0m02"],
		N["L0m02"],
		N["L0m02"],
		N["_____"],N["_____"],N["_____"],N["_____"],N["_____"],N["_____"],N["_____"],N["_____"],N["_____"],N["_____"],N["_____"],N["_____"],N["_____"],N["_____"],N["_____"],N["_____"],N["_____"],N["_____"],N["_____"],N["_____"],N["_____"],N["_____"],N["_____"],N["_____"],N["_____"],N["_____"],N["_____"],N["_____"],N["_____"],N["_____"],N["_____"],N["_____"],N["_____"],N["_____"],N["_____"],N["_____"],N["_____"],N["_____"],N["_____"],N["_____"],N["_____"],N["_____"],N["_____"],N["_____"],N["_____"],N["_____"],N["_____"],N["_____"],N["_____"],N["_____"],N["_____"],N["_____"],N["_____"],N["_____"],N["_____"],N["_____"],N["_____"],N["_____"],N["_____"],N["_____"],N["_____"],N["_____"],N["_____"],N["_____"],N["_____"],N["_____"],N["_____"],N["_____"],N["_____"],N["_____"],N["_____"],N["_____"],N["_____"],
		N["L0m02"],
		N["L0m02"],
		N["L0m02"],
		N["_____"],N["_____"],N["_____"],N["_____"],N["_____"],N["_____"],N["_____"],
		{name = "australia:lilly_pilly_berries",param1 = 127},
		N["L0m02"],
		N["L0m02"],
		N["L0m02"],
		N["L0m02"],
		N["_____"],N["_____"],N["_____"],N["_____"],N["_____"],N["_____"],
		N["L0m02"],
		N["L0m02"],
		N["L0m01"],
		N["L0m02"],
		N["L0m02"],
		N["_____"],N["_____"],N["_____"],N["_____"],N["_____"],
		N["L0m02"],
		N["L0m02"],
		N["L0m02"],
		N["L0m02"],
		N["L0m02"],
		N["L0m02"],
		{name = "australia:lilly_pilly_berries",param1 = 127},
		N["_____"],N["_____"],N["_____"],N["_____"],
		N["L0m02"],
		N["L0m01"],
		N["L0m01"],
		N["L0m01"],
		N["L0m01"],
		N["L0m02"],
		N["L0m02"],
		N["_____"],N["_____"],N["_____"],N["_____"],
		N["L0m02"],
		N["L0m01"],
		N["L0m00"],
		N["L0m01"],
		N["L0m02"],
		N["L0m02"],
		{name = "australia:lilly_pilly_berries",param1 = 127},
		N["_____"],N["_____"],N["_____"],N["_____"],
		N["L0m02"],
		N["L0m01"],
		N["L0m01"],
		N["L0m01"],
		N["L0m01"],
		N["L0m02"],
		N["L0m02"],
		N["_____"],N["_____"],N["_____"],N["_____"],
		N["L0m02"],
		N["L0m02"],
		N["L0m01"],
		N["L0m00"],
		N["L0m01"],
		N["L0m01"],
		N["L0m02"],
		N["_____"],N["_____"],N["_____"],N["_____"],
		N["L0m02"],
		{name = "australia:lilly_pilly_berries",param1 = 127},
		N["L0m01"],
		N["L0m01"],
		N["L0m00"],
		N["L0m01"],
		N["L0m02"],
		N["_____"],N["_____"],N["_____"],N["_____"],N["_____"],
		N["L0m02"],
		N["L0m02"],
		N["L0m01"],
		N["L0m01"],
		N["L0m01"],
		N["L0m02"],
		N["_____"],N["_____"],N["_____"],N["_____"],N["_____"],
		N["L0m02"],
		N["L0m02"],
		N["L0m01"],
		N["L0m02"],
		N["L0m02"],
		N["L0m02"],
		N["_____"],N["_____"],N["_____"],N["_____"],N["_____"],
		N["L0m02"],
		N["L0m02"],
		N["L0m02"],
		N["L0m02"],
		N["L0m02"],
		N["_____"],N["_____"],N["_____"],N["_____"],N["_____"],N["_____"],N["_____"],
		N["L0m02"],
		N["L0m02"],
		N["L0m02"],
		N["_____"],N["_____"],N["_____"],N["_____"],N["_____"],N["_____"],N["_____"],N["_____"],N["_____"],N["_____"],N["_____"],N["_____"],N["_____"],N["_____"],N["_____"],N["_____"],N["_____"],N["_____"],N["_____"],N["_____"],N["_____"],N["_____"],N["_____"],N["_____"],N["_____"],N["_____"],N["_____"],N["_____"],N["_____"],N["_____"],N["_____"],N["_____"],N["_____"],N["_____"],N["_____"],N["_____"],N["_____"],N["_____"],N["_____"],N["_____"],N["_____"],N["_____"],N["_____"],N["_____"],N["_____"],N["_____"],N["_____"],N["_____"],N["_____"],N["_____"],N["_____"],N["_____"],N["_____"],N["_____"],N["_____"],N["_____"],N["_____"],N["_____"],N["_____"],N["_____"],N["_____"],N["_____"],N["_____"],N["_____"],N["_____"],N["_____"],N["_____"],N["_____"],N["_____"],N["_____"],N["_____"],N["_____"],N["_____"],N["_____"],N["_____"],N["_____"],N["_____"],N["_____"],N["_____"],N["_____"],N["_____"],N["_____"],N["_____"],N["_____"],N["_____"],N["_____"],N["_____"],N["_____"],N["_____"],N["_____"],N["_____"],N["_____"],N["_____"],N["_____"],N["_____"],N["_____"],N["_____"],
		N["L0m02"],
		N["_____"],N["_____"],N["_____"],N["_____"],N["_____"],N["_____"],N["_____"],N["_____"],
		N["L0m02"],
		N["L0m02"],
		N["L0m02"],
		N["_____"],N["_____"],N["_____"],N["_____"],N["_____"],N["_____"],N["_____"],
		N["L0m02"],
		N["L0m02"],
		N["L0m02"],
		N["L0m02"],
		N["L0m02"],
		N["_____"],N["_____"],N["_____"],N["_____"],N["_____"],N["_____"],
		N["L0m02"],
		N["L0m02"],
		N["L0m01"],
		N["L0m02"],
		N["L0m02"],
		N["_____"],N["_____"],N["_____"],N["_____"],N["_____"],N["_____"],
		N["L0m02"],
		N["L0m02"],
		N["L0m02"],
		N["L0m02"],
		N["L0m02"],
		N["L0m02"],
		N["_____"],N["_____"],N["_____"],N["_____"],N["_____"],N["_____"],
		N["L0m02"],
		N["L0m02"],
		N["L0m01"],
		N["L0m02"],
		N["L0m02"],
		N["L0m02"],
		N["_____"],N["_____"],N["_____"],N["_____"],N["_____"],
		N["L0m02"],
		N["L0m02"],
		N["L0m02"],
		N["L0m01"],
		N["L0m02"],
		{name = "australia:lilly_pilly_berries",param1 = 127},
		N["_____"],N["_____"],N["_____"],N["_____"],N["_____"],N["_____"],
		N["L0m02"],
		{name = "australia:lilly_pilly_berries",param1 = 127},
		N["L0m02"],
		N["L0m02"],
		N["L0m02"],
		N["_____"],N["_____"],N["_____"],N["_____"],N["_____"],N["_____"],N["_____"],
		N["L0m02"],
		N["L0m02"],
		N["L0m02"],
		N["_____"],N["_____"],N["_____"],N["_____"],N["_____"],N["_____"],N["_____"],N["_____"],N["_____"],N["_____"],N["_____"],N["_____"],N["_____"],N["_____"],N["_____"],N["_____"],N["_____"],N["_____"],N["_____"],N["_____"],N["_____"],N["_____"],N["_____"],N["_____"],N["_____"],N["_____"],N["_____"],N["_____"],N["_____"],N["_____"],N["_____"],N["_____"],N["_____"],N["_____"],N["_____"],N["_____"],N["_____"],N["_____"],N["_____"],N["_____"],N["_____"],N["_____"],N["_____"],N["_____"],N["_____"],N["_____"],N["_____"],N["_____"],N["_____"],N["_____"],N["_____"],N["_____"],N["_____"],N["_____"],N["_____"],N["_____"],N["_____"],N["_____"],N["_____"],N["_____"],N["_____"],N["_____"],N["_____"],N["_____"],N["_____"],N["_____"],N["_____"],N["_____"],N["_____"],N["_____"],N["_____"],N["_____"],N["_____"],N["_____"],N["_____"],N["_____"],N["_____"],N["_____"],N["_____"],N["_____"],N["_____"],N["_____"],N["_____"],N["_____"],N["_____"],N["_____"],N["_____"],N["_____"],N["_____"],N["_____"],N["_____"],N["_____"],N["_____"],N["_____"],N["_____"],N["_____"],N["_____"],N["_____"],N["_____"],N["_____"],N["_____"],N["_____"],N["_____"],N["_____"],N["_____"],N["_____"],N["_____"],N["_____"],N["_____"],N["_____"],N["_____"],N["_____"],N["_____"],N["_____"],N["_____"],N["_____"],N["_____"],N["_____"],N["_____"],N["_____"],N["_____"],N["_____"],N["_____"],N["_____"],N["_____"],N["_____"],N["_____"],N["_____"],N["_____"],N["_____"],N["_____"],N["_____"],N["_____"],N["_____"],N["_____"],N["_____"],N["_____"],N["_____"],N["_____"],N["_____"],N["_____"],N["_____"],N["_____"],N["_____"],N["_____"],N["_____"],N["_____"],N["_____"],N["_____"],N["_____"],
		{name = "australia:lilly_pilly_berries",param1 = 127},
		N["_____"],N["_____"],N["_____"],N["_____"],N["_____"],N["_____"],N["_____"],N["_____"],N["_____"],N["_____"],N["_____"],N["_____"],N["_____"],N["_____"],N["_____"],N["_____"],N["_____"],N["_____"],N["_____"],N["_____"],N["_____"],N["_____"],
		N["L0m02"],
		N["_____"],N["_____"],N["_____"],N["_____"],N["_____"],N["_____"],N["_____"],N["_____"],N["_____"],N["_____"],N["_____"],
		N["L0m02"],
		N["_____"],N["_____"],N["_____"],N["_____"],N["_____"],N["_____"],N["_____"],N["_____"],N["_____"],N["_____"],N["_____"],N["_____"],N["_____"],N["_____"],N["_____"],N["_____"],N["_____"],N["_____"],N["_____"],N["_____"],N["_____"],N["_____"],N["_____"],N["_____"],N["_____"],N["_____"],N["_____"],N["_____"],N["_____"],N["_____"],N["_____"],N["_____"],N["_____"],N["_____"],N["_____"],N["_____"],N["_____"],N["_____"],N["_____"],N["_____"],N["_____"],N["_____"],N["_____"],N["_____"],N["_____"],N["_____"],N["_____"],N["_____"],N["_____"],N["_____"],N["_____"],N["_____"],N["_____"],N["_____"],N["_____"],N["_____"],N["_____"],N["_____"],N["_____"],N["_____"],N["_____"],N["_____"],N["_____"],N["_____"],N["_____"],N["_____"],N["_____"],N["_____"],N["_____"],N["_____"],N["_____"],N["_____"],N["_____"],N["_____"],N["_____"],N["_____"],N["_____"],N["_____"],N["_____"],N["_____"],N["_____"],N["_____"],N["_____"],N["_____"],N["_____"],N["_____"],N["_____"],N["_____"],N["_____"],N["_____"],N["_____"],N["_____"],N["_____"],N["_____"],N["_____"],N["_____"],N["_____"],N["_____"],N["_____"],N["_____"],N["_____"],N["_____"],N["_____"],N["_____"],N["_____"],N["_____"],N["_____"],N["_____"],N["_____"],N["_____"],N["_____"],N["_____"],N["_____"],N["_____"],N["_____"],N["_____"],N["_____"],N["_____"],N["_____"],N["_____"],N["_____"],N["_____"],N["_____"],N["_____"],N["_____"],N["_____"],N["_____"],N["_____"],N["_____"],N["_____"],N["_____"],N["_____"],N["_____"],N["_____"],N["_____"],N["_____"],N["_____"],N["_____"],N["_____"],N["_____"],N["_____"],N["_____"],N["_____"],N["_____"],N["_____"],N["_____"],N["_____"],N["_____"],N["_____"],N["_____"],N["_____"],N["_____"],N["_____"],N["_____"],N["_____"],N["_____"],N["_____"],N["_____"],N["_____"],N["_____"],N["_____"],N["_____"],N["_____"],N["_____"],N["_____"],N["_____"],N["_____"],N["_____"],N["_____"],N["_____"],N["_____"],N["_____"],N["_____"],N["_____"],N["_____"],N["_____"],N["_____"],N["_____"],N["_____"],N["_____"],N["_____"],N["_____"],N["_____"],N["_____"],N["_____"],N["_____"],N["_____"],N["_____"],N["_____"],N["_____"],N["_____"],N["_____"],N["_____"],N["_____"],N["_____"],N["_____"],N["_____"],N["_____"],N["_____"],N["_____"],N["_____"],N["_____"],N["_____"],N["_____"],N["_____"],N["_____"],N["_____"],N["_____"],N["_____"],N["_____"],N["_____"],N["_____"],N["_____"],N["_____"],N["_____"],N["_____"],N["_____"],N["_____"],N["_____"],N["_____"],N["_____"],N["_____"],N["_____"],N["_____"],N["_____"],N["_____"],N["_____"],N["_____"],N["_____"],N["_____"],N["_____"],N["_____"],N["_____"],N["_____"],N["_____"],N["_____"],N["_____"],N["_____"],N["_____"],N["_____"],N["_____"],N["_____"],N["_____"],N["_____"],N["_____"],N["_____"],N["_____"],N["_____"],N["_____"],N["_____"],N["_____"],N["_____"],N["_____"],N["_____"],N["_____"],N["_____"],N["_____"],N["_____"],N["_____"],N["_____"],N["_____"],N["_____"],N["_____"],N["_____"],N["_____"],N["_____"],N["_____"],N["_____"]
	}
}