{
	yslice_prob = {
		{ypos = 0, prob = 254},
		{ypos = 1, prob = 254},
		{ypos = 2, prob = 254},
		{ypos = 3, prob = 254},
		{ypos = 4, prob = 254},
		{ypos = 5, prob = 254},
		{ypos = 6, prob = 254},
		{ypos = 7, prob = 254},
		{ypos = 8, prob = 254},
		{ypos = 9, prob = 254},
		{ypos = 10, prob = 254}
	},
	size = {
		y = 11,
		x = 9,
		z = 9
	},
	data = {
		MZ, MZ, MZ, MZ, MZ, MZ, MZ, MZ, MZ, __, __, __, __, __, __, __, __, __, __, __, __, __, __, __, __, __, __, __, __, {param2 = 1, name = "gal:item_reed_wet_roof_corner", prob = 254},
		{param2 = 0, name = "gal:item_reed_wet_roof", prob = 254},
		{param2 = 0, name = "gal:item_reed_wet_roof", prob = 254},
		{param2 = 0, name = "gal:item_reed_wet_roof", prob = 254},
		{param2 = 0, name = "gal:item_reed_wet_roof_corner", prob = 254},
		__, __, __, __, __, __, __, __, __, __, __, __, __, __, __, __, __, __, __, __, __, __, __, __, __, __, __, __, __, __, __, __, __, __, __, __, __, __, __, __, __, __, __, __, __, __, __, __, __, __, __, __, __, __, __, __, __, __, __, __, __, __, __, __, __, MZ, MZ, MZ, MZ, MZ, MZ, MZ, MZ, MZ, __, __, {param2 = 9, name = "gal:item_reed_dry_slab", prob = 254},
		{param2 = 5, name = "gal:item_reed_dry_slab", prob = 254},
		{param2 = 0, name = "cottages:half_door_inverted", prob = 254},
		{param2 = 5, name = "gal:item_reed_dry_slab", prob = 254},
		{param2 = 9, name = "gal:item_reed_dry_slab", prob = 254},
		__, __, __, __, {param2 = 9, name = "gal:item_reed_dry_slab", prob = 254},
		{param2 = 5, name = "gal:item_reed_dry_slab", prob = 254},
		{param2 = 0, name = "cottages:half_door_inverted", prob = 254},
		{param2 = 5, name = "gal:item_reed_dry_slab", prob = 254},
		{param2 = 9, name = "gal:item_reed_dry_slab", prob = 254},
		__, __, __, {param2 = 1, name = "gal:item_reed_wet_roof_corner", prob = 254},
		{param2 = 2, name = "gal:item_reed_wet_roof", prob = 254},
		{param2 = 5, name = "gal:item_reed_dry_slab", prob = 254},
		{param2 = 5, name = "gal:item_reed_dry_slab", prob = 254},
		{param2 = 5, name = "gal:item_reed_dry_slab", prob = 254},
		{param2 = 2, name = "gal:item_reed_wet_roof", prob = 254},
		{param2 = 0, name = "gal:item_reed_wet_roof_corner", prob = 254},
		__, __, __, {param2 = 1, name = "gal:item_reed_wet_roof_corner", prob = 254},
		{param2 = 0, name = "gal:item_reed_wet_roof", prob = 254},
		{param2 = 0, name = "gal:item_reed_wet_roof", prob = 254},
		{param2 = 0, name = "gal:item_reed_wet_roof", prob = 254},
		{param2 = 0, name = "gal:item_reed_wet_roof_corner", prob = 254},
		__, __, __, __, __, __, __, __, __, __, __, __, __, __, __, __, __, __, __, __, __, __, __, __, __, __, __, __, __, __, __, __, __, __, __, __, __, __, __, __, __, __, __, __, __, __, __, __, __, __, __, __, __, __, __, __, MZ, MZ, MZ, MZ, MZ, MZ, MZ, MZ, MZ, __, {param2 = 17, name = "gal:item_reed_dry_slab", prob = 254},
		{param2 = 3, name = "cottages:sleeping_mat", prob = 254},
		{param2 = 3, name = "cottages:sleeping_mat", prob = 254},
		__, {param2 = 3, name = "cottages:sleeping_mat", prob = 254},
		{param2 = 3, name = "cottages:sleeping_mat", prob = 254},
		{param2 = 13, name = "gal:item_reed_dry_slab", prob = 254},
		__, __, {param2 = 17, name = "gal:item_reed_dry_slab", prob = 254},
		__, __, __, __, __, {param2 = 13, name = "gal:item_reed_dry_slab", prob = 254},
		__, {param2 = 1, name = "gal:item_reed_wet_roof_corner", prob = 254},
		{param2 = 3, name = "gal:item_reed_wet_roof", prob = 254},
		__, __, __, __, __, {param2 = 1, name = "gal:item_reed_wet_roof", prob = 254},
		{param2 = 0, name = "gal:item_reed_wet_roof_corner", prob = 254},
		__, {param2 = 1, name = "gal:item_reed_wet_roof_corner", prob = 254},
		{param2 = 21, name = "gal:item_reed_wet_slab", prob = 254},
		__, __, __, {param2 = 21, name = "gal:item_reed_wet_slab", prob = 254},
		{param2 = 0, name = "gal:item_reed_wet_roof_corner", prob = 254},
		__, __, __, {param2 = 1, name = "gal:item_reed_wet_roof_corner", prob = 254},
		{param2 = 0, name = "gal:item_reed_wet_roof", prob = 254},
		{param2 = 0, name = "gal:item_reed_wet_roof", prob = 254},
		{param2 = 0, name = "gal:item_reed_wet_roof", prob = 254},
		{param2 = 0, name = "gal:item_reed_wet_roof_corner", prob = 254},
		__, __, __, __, __, __, __, __, __, __, __, __, __, __, __, __, __, __, __, __, __, __, __, __, __, __, __, __, __, __, __, __, __, __, __, __, __, __, __, __, __, __, __, __, __, __, __, MZ, MZ, MZ, MZ, MZ, MZ, MZ, MZ, MZ, __, {param2 = 13, name = "gal:item_reed_dry_slab", prob = 254},
		{param2 = 3, name = "cottages:sleeping_mat", prob = 254},
		__, __, __, {param2 = 3, name = "cottages:sleeping_mat", prob = 254},
		{param2 = 17, name = "gal:item_reed_dry_slab", prob = 254},
		__, __, {param2 = 13, name = "gal:item_reed_dry_slab", prob = 254},
		__, __, __, __, __, {param2 = 17, name = "gal:item_reed_dry_slab", prob = 254},
		__, {param2 = 1, name = "gal:item_reed_wet_roof", prob = 254},
		{param2 = 13, name = "gal:item_reed_dry_slab", prob = 254},
		__, __, __, __, __, {param2 = 17, name = "gal:item_reed_dry_slab", prob = 254},
		{param2 = 3, name = "gal:item_reed_wet_roof", prob = 254},
		__, {param2 = 1, name = "gal:item_reed_wet_roof", prob = 254},
		__, __, __, __, __, {param2 = 3, name = "gal:item_reed_wet_roof", prob = 254},
		__, __, __, {param2 = 1, name = "gal:item_reed_wet_roof", prob = 254},
		{param2 = 21, name = "gal:item_reed_wet_slab", prob = 254},
		__, {param2 = 21, name = "gal:item_reed_wet_slab", prob = 254},
		{param2 = 3, name = "gal:item_reed_wet_roof", prob = 254},
		__, __, __, __, __, {param2 = 1, name = "gal:item_reed_wet_roof_corner", prob = 254},
		{param2 = 0, name = "gal:item_reed_wet_roof", prob = 254},
		{param2 = 0, name = "gal:item_reed_wet_roof_corner", prob = 254},
		__, __, __, __, __, __, __, __, __, __, __, __, __, __, __, __, __, __, __, __, __, __, __, __, __, __, __, __, __, __, __, __, __, __, __, __, __, __, __, MZ, MZ, MZ, MZ, MZ, MZ, MZ, MZ, MZ, {param2 = 17, name = "gal:item_reed_dry_slab", prob = 254},
		{param2 = 3, name = "cottages:sleeping_mat", prob = 254},
		__, __, __, __, __, {param2 = 3, name = "cottages:sleeping_mat", prob = 254},
		{param2 = 13, name = "gal:item_reed_dry_slab", prob = 254},
		{param2 = 3, name = "cottages:half_door_inverted", prob = 254},
		__, __, __, __, __, __, {param2 = 1, name = "cottages:half_door", prob = 254},
		__, {param2 = 1, name = "gal:item_reed_wet_roof", prob = 254},
		{param2 = 13, name = "gal:item_reed_dry_slab", prob = 254},
		__, __, __, __, __, {param2 = 17, name = "gal:item_reed_dry_slab", prob = 254},
		{param2 = 3, name = "gal:item_reed_wet_roof", prob = 254},
		__, {param2 = 1, name = "gal:item_reed_wet_roof", prob = 254},
		__, __, __, __, __, {param2 = 3, name = "gal:item_reed_wet_roof", prob = 254},
		__, __, __, {param2 = 1, name = "gal:item_reed_wet_roof", prob = 254},
		__, __, __, {param2 = 3, name = "gal:item_reed_wet_roof", prob = 254},
		__, __, __, __, __, {param2 = 1, name = "gal:item_reed_wet_roof", prob = 254},
		__, {param2 = 3, name = "gal:item_reed_wet_roof", prob = 254},
		__, __, __, __, __, __, __, {param2 = 0, name = "gal:item_reed_wet_slab", prob = 254},
		__, __, __, __, __, __, __, __, __, __, __, __, __, __, __, __, __, __, __, __, __, __, __, __, __, __, __, __, __, __, __, MZ, MZ, MZ, MZ, MZ, MZ, MZ, MZ, MZ, __, {param2 = 13, name = "gal:item_reed_dry_slab", prob = 254},
		{param2 = 3, name = "cottages:sleeping_mat", prob = 254},
		__, {param2 = 0, name = "mg_villages:mob_workplace_marker", prob = 254},
		__, {param2 = 3, name = "cottages:sleeping_mat", prob = 254},
		{param2 = 17, name = "gal:item_reed_dry_slab", prob = 254},
		__, __, {param2 = 13, name = "gal:item_reed_dry_slab", prob = 254},
		__, __, __, __, __, {param2 = 17, name = "gal:item_reed_dry_slab", prob = 254},
		__, {param2 = 1, name = "gal:item_reed_wet_roof", prob = 254},
		{param2 = 13, name = "gal:item_reed_dry_slab", prob = 254},
		__, __, __, __, __, {param2 = 17, name = "gal:item_reed_dry_slab", prob = 254},
		{param2 = 3, name = "gal:item_reed_wet_roof", prob = 254},
		__, {param2 = 1, name = "gal:item_reed_wet_roof", prob = 254},
		__, __, __, __, __, {param2 = 3, name = "gal:item_reed_wet_roof", prob = 254},
		__, __, __, {param2 = 1, name = "gal:item_reed_wet_roof", prob = 254},
		{param2 = 21, name = "gal:item_reed_wet_slab", prob = 254},
		__, {param2 = 21, name = "gal:item_reed_wet_slab", prob = 254},
		{param2 = 3, name = "gal:item_reed_wet_roof", prob = 254},
		__, __, __, __, __, {param2 = 2, name = "gal:item_reed_wet_roof_corner", prob = 254},
		{param2 = 2, name = "gal:item_reed_wet_roof", prob = 254},
		{param2 = 3, name = "gal:item_reed_wet_roof_corner", prob = 254},
		__, __, __, __, __, __, __, __, __, __, __, __, __, __, __, __, __, __, __, __, __, __, __, __, __, __, __, __, __, __, __, __, __, __, __, __, __, __, __, MZ, MZ, MZ, MZ, MZ, MZ, MZ, MZ, MZ, __, {param2 = 17, name = "gal:item_reed_dry_slab", prob = 254},
		{param2 = 3, name = "cottages:sleeping_mat", prob = 254},
		{param2 = 3, name = "cottages:sleeping_mat", prob = 254},
		__, {param2 = 3, name = "cottages:sleeping_mat", prob = 254},
		{param2 = 3, name = "cottages:sleeping_mat", prob = 254},
		{param2 = 13, name = "gal:item_reed_dry_slab", prob = 254},
		__, __, {param2 = 17, name = "gal:item_reed_dry_slab", prob = 254},
		__, __, __, __, __, {param2 = 13, name = "gal:item_reed_dry_slab", prob = 254},
		__, {param2 = 2, name = "gal:item_reed_wet_roof_corner", prob = 254},
		{param2 = 3, name = "gal:item_reed_wet_roof", prob = 254},
		__, __, __, __, __, {param2 = 1, name = "gal:item_reed_wet_roof", prob = 254},
		{param2 = 3, name = "gal:item_reed_wet_roof_corner", prob = 254},
		__, {param2 = 2, name = "gal:item_reed_wet_roof_corner", prob = 254},
		{param2 = 21, name = "gal:item_reed_wet_slab", prob = 254},
		__, __, __, {param2 = 21, name = "gal:item_reed_wet_slab", prob = 254},
		{param2 = 3, name = "gal:item_reed_wet_roof_corner", prob = 254},
		__, __, __, {param2 = 2, name = "gal:item_reed_wet_roof_corner", prob = 254},
		{param2 = 2, name = "gal:item_reed_wet_roof", prob = 254},
		{param2 = 2, name = "gal:item_reed_wet_roof", prob = 254},
		{param2 = 2, name = "gal:item_reed_wet_roof", prob = 254},
		{param2 = 3, name = "gal:item_reed_wet_roof_corner", prob = 254},
		__, __, __, __, __, __, __, __, __, __, __, __, __, __, __, __, __, __, __, __, __, __, __, __, __, __, __, __, __, __, __, __, __, __, __, __, __, __, __, __, __, __, __, __, __, __, __, MZ, MZ, MZ, MZ, MZ, MZ, MZ, MZ, MZ, __, __, {param2 = 5, name = "gal:item_reed_dry_slab", prob = 254},
		{param2 = 9, name = "gal:item_reed_dry_slab", prob = 254},
		{param2 = 3, name = "cottages:sleeping_mat", prob = 254},
		{param2 = 9, name = "gal:item_reed_dry_slab", prob = 254},
		{param2 = 5, name = "gal:item_reed_dry_slab", prob = 254},
		__, __, __, __, {param2 = 5, name = "gal:item_reed_dry_slab", prob = 254},
		{param2 = 9, name = "gal:item_reed_dry_slab", prob = 254},
		__, {param2 = 9, name = "gal:item_reed_dry_slab", prob = 254},
		{param2 = 5, name = "gal:item_reed_dry_slab", prob = 254},
		__, __, __, {param2 = 2, name = "gal:item_reed_wet_roof_corner", prob = 254},
		{param2 = 0, name = "gal:item_reed_wet_roof", prob = 254},
		{param2 = 9, name = "gal:item_reed_dry_slab", prob = 254},
		__, {param2 = 9, name = "gal:item_reed_dry_slab", prob = 254},
		{param2 = 0, name = "gal:item_reed_wet_roof", prob = 254},
		{param2 = 3, name = "gal:item_reed_wet_roof_corner", prob = 254},
		__, __, __, {param2 = 2, name = "gal:item_reed_wet_roof_corner", prob = 254},
		{param2 = 2, name = "gal:item_reed_wet_roof", prob = 254},
		{param2 = 2, name = "gal:item_reed_wet_roof", prob = 254},
		{param2 = 2, name = "gal:item_reed_wet_roof", prob = 254},
		{param2 = 3, name = "gal:item_reed_wet_roof_corner", prob = 254},
		__, __, __, __, __, __, __, __, __, __, __, __, __, __, __, __, __, __, __, __, __, __, __, __, __, __, __, __, __, __, __, __, __, __, __, __, __, __, __, __, __, __, __, __, __, __, __, __, __, __, __, __, __, __, __, __, MZ, MZ, MZ, MZ, MZ, MZ, MZ, MZ, MZ, __, __, __, __, {param2 = 5, name = "gal:item_reed_dry_slab", prob = 254},
		__, __, __, __, __, __, __, __, {param2 = 5, name = "gal:item_reed_dry_slab", prob = 254},
		__, __, __, __, __, __, {param2 = 2, name = "gal:item_reed_wet_roof_corner", prob = 254},
		{param2 = 2, name = "gal:item_reed_wet_roof", prob = 254},
		{param2 = 2, name = "gal:item_reed_wet_roof", prob = 254},
		{param2 = 2, name = "gal:item_reed_wet_roof", prob = 254},
		{param2 = 3, name = "gal:item_reed_wet_roof_corner", prob = 254},
		__, __, __, __, __, __, __, __, __, __, __, __, __, __, __, __, __, __, __, __, __, __, __, __, __, __, __, __, __, __, __, __, __, __, __, __, __, __, __, __, __, __, __, __, __, __, __, __, __, __, __, __, __, __, __, __, __, __, __, __, __, __, __, __, {param2 = 0, name = "air", prob = 254}
	}
}